Workbook

Sheet Instructions
B2: How to Use This Planner
B3: This workbook compares two ways to spend down a retirement portfolio: the classic 4% rule and a more flexible "dynamic" strategy from the Wall Street Journal article (see the Article tab). It is an educational illustration, not financial advice.
B5: How the strategies work
B6: 4% rule — withdraw 4% of the starting portfolio in year one, then raise that dollar amount by inflation every year (created by William Bengen, 1994). Simple, but rigid.
B7: Dynamic strategy — three layered fixes the article recommends:
B8: 1) Life expectancy: each year divide your balance by your remaining years and spend that share.
B9: 2) Guardrails: keep the result inside a band (floor / ceiling) so spending never gets extreme.
B10: 3) Shock absorber: never change spending by more than a set % in a single year.
B11: Essentials vs. discretionary — cover must-haves with guaranteed income; apply the dynamic withdrawals to the rest. The Essentials Check shows how much of your essentials the portfolio must still cover.
B13: Quick start
B14: 1. Open the Inputs & Summary tab.
B15: 2. Change any of the yellow cells to match your situation (age, portfolio size, returns, etc.).
... B66: Defaults: 6% expected return (nominal), 3% inflation, 4% rule rate, 3%–6% guardrails, 5% shock absorber. A 3% inflation assumption is reasonable and slightly conservative (long-run US inflation has averaged about 2.5–3%). Adjust any of these to your own outlook.

Sheet Inputs & Summary
B2: Retirement Withdrawal Strategies
B3: Compare the classic 4% rule with a dynamic strategy (life-expectancy + guardrails + shock absorber). Yellow = inputs you can change · Black = calculated · Green = pulled from another tab. See the Instructions tab.
B4: ="At a starting portfolio of "&TEXT($C$9,"$#,##0")&": 4% rule "&IF($F$11="YES","lasts to age "&$C$8,"runs out before age "&$C$8)&" (about "&TEXT($F$10,"$#,##0")&" left). Dynamic strategy "&IF($F$18="YES","lasts to age "&$C$8,"runs out before age "&$C$8)&", with annual withdrawals of "&TEXT($F$14,"$#,##0")&" to "&TEXT($F$15,"$#,##0")&"." -> At a starting portfolio of $3,500,000: 4% rule lasts to age 90 (about $847,494 left). Dynamic strategy lasts to age 90, with annual withdrawals of $110,063 to $285,584.
H5: SCENARIO DETAIL — annual returns (edit yellow cells)
B6: ASSUMPTIONS (edit the yellow cells) | E6: RESULTS | H6: Year | I6: Early crash | J6: Stagflation
B7: Retirement start age (or current age, if retired) | C7: 50 | E7: Years modeled (start -> plan-to age) | F7: =$C$8-$C$7 -> 40 | H7: 1 | I7: -0.2 | J7: 0.01
B8: Plan-to age (planning horizon) | C8: 90 | E8: — 4% RULE — | H8: 2 | I8: -0.1 | J8: 0.01
B9: Starting portfolio at retirement (or current portfolio amount, if retired) | C9: 3500000 | E9: First-year withdrawal (today's $) | F9: ='4% Rule'!$E$5 -> 140000 | H9: 3 | I9: 0.15 | J9: 0.01
B10: Expected annual return (nominal, default) | C10: 0.06 | E10: Balance at plan-to age (future $) | F10: =INDEX('4% Rule'!$H$5:$H$50,MIN(MAX($C$8-$C$7+1,1),46)) -> 847494.42 | H10: 4 | I10: 0.15 | J10: 0.01
B11: Inflation rate | C11: 0.03 | E11: Money lasts to plan-to age? | F11: =IF(INDEX('4% Rule'!$H$5:$H$50,MIN(MAX($C$8-$C$7+1,1),46))>0,"YES","NO") -> YES | H11: 5 | I11: 0.12 | J11: 0.01
B12: 4% rule starting rate | C12: 0.04 | E12: — DYNAMIC STRATEGY — | H12: 6 | I12: =$C$10 -> 0.06 | J12: 0.01
B13: Guardrail floor (minimum withdrawal rate) | C13: 0.03 | E13: First-year withdrawal (today's $) | F13: ='Dynamic Strategy'!$H$5 -> 110062.89 | H13: 7 | I13: =$C$10 -> 0.06 | J13: 0.01
B14: Guardrail ceiling (maximum withdrawal rate) | C14: 0.06 | E14: Lowest annual withdrawal (future $) | F14: =MIN('Dynamic Strategy'!$H$5:$H$50) -> 110062.89 | H14: 8 | I14: =$C$10 -> 0.06 | J14: 0.01
B15: Shock absorber — max spending change per year | C15: 0.05 | E15: Highest annual withdrawal (future $) | F15: =MAX('Dynamic Strategy'!$H$5:$H$50) -> 285583.58 | H15: 9 | I15: =$C$10 -> 0.06 | J15: =$C$10 -> 0.06
B16: Essential annual spending (today's $) | C16: 100000 | E16: Balance at plan-to age (future $) | F16: =INDEX('Dynamic Strategy'!$L$5:$L$50,MIN(MAX($C$8-$C$7+1,1),46)) -> 4421942.8 | H16: 10 | I16: =$C$10 -> 0.06 | J16: =$C$10 -> 0.06
B17: Full Social Security benefit at age 67 / FRA (today's $/yr) | C17: 30000 | E17: Balance at plan-to age (today's $) | F17: =INDEX('Dynamic Strategy'!$M$5:$M$50,MIN(MAX($C$8-$C$7+1,1),46)) -> 1355576.8 | H17: Years beyond 10 use your expected return.
B18: Social Security start age (62–70) | C18: 67 | E18: Money lasts to plan-to age? | F18: =IF(INDEX('Dynamic Strategy'!$L$5:$L$50,MIN(MAX($C$8-$C$7+1,1),46))>0,"YES","NO") -> YES
B19: Current 4% rule withdrawal if already retired (today's $/yr; 0 if not) | C19: 0 | E19: Years total spending falls below essentials | F19: =SUMPRODUCT(('Dynamic Strategy'!$B$5:$B$50<=$C$8)*('Dynamic Strategy'!$P$5:$P$50<$C$16)) -> 0 | H19: SOCIAL SECURITY — % of full benefit by start age
E20: — ESSENTIALS CHECK — | H20: Start age | I20: % of full
B21: MARKET SCENARIO | E21: Essential spending not covered by Social Security, once collecting (today's $) | F21: =MAX($C$16-($C$17*VLOOKUP($C$18,$H$21:$I$29,2,FALSE)),0) -> 70000 | H21: 62 | I21: 0.7
B22: Market scenario (drives the return column) | C22: Steady | H22: 63 | I22: 0.75
H23: 64 | I23: 0.8
B24: LIFE EXPECTANCY ANCHORS (SSA cohort) | H24: 65 | I24: 0.867
B25: Current age (for life expectancy) | C25: 49 | H25: 66 | I25: 0.933
B26: Remaining life expectancy at current age | C26: 32.6 | H26: 67 | I26: 1
B27: Remaining life expectancy at age 62 | C27: 22.4 | H27: 68 | I27: 1.08
B28: Remaining life expectancy at age 67 | C28: 18.8 | H28: 69 | I28: 1.16
B29: Remaining life expectancy at age 70 | C29: 16.7 | H29: 70 | I29: 1.24
H30: Source: SSA, born 1960 or later (FRA 67). ssa.gov/benefits/retirement/planner/1960.html
B31: Visual comparison
B64: Educational illustration, not financial advice. Source: WSJ, "The 4% Rule for Retirement Is Too Simple. Here's a Better Way." Life-expectancy figures are SSA cohort life-table values (born 1960 or later).

Sheet Dynamic Strategy
A1: Dynamic Strategy — Year by Year
A2: Withdrawal = balance / remaining years, kept inside the guardrails, then limited by the shock absorber. Returns are linked to the 4% Rule tab for an apples-to-apples comparison.
A4: Year | B4: Age | C4: Remaining years | D4: Annual return | E4: Beginning balance | F4: Life-exp. withdrawal | G4: After guardrails | H4: Final withdrawal | I4: Final withdrawal (today's $) | J4: Implied rate | K4: Investment return | L4: Ending balance | M4: Ending balance (today's $) | N4: Social Security | O4: Total spending | P4: Total spending (today's $)
A5: 1 | B5: ='Inputs & Summary'!$C$7+1-1 -> 50 | C5: =IFERROR(VLOOKUP(B5,'Life Expectancy'!$A$6:$B$81,2,FALSE),1.5) -> 31.8 | D5: ='4% Rule'!C5 -> 0.06 | E5: ='Inputs & Summary'!$C$9 -> 3500000 | F5: =E5/MAX(C5,1) -> 110062.89 | G5: =MIN('Inputs & Summary'!$C$14*E5,MAX('Inputs & Summary'!$C$13*E5,F5)) -> 110062.89 | H5: =MIN(G5,E5) -> 110062.89 | I5: =H5/(1+'Inputs & Summary'!$C$11)^(1-1) -> 110062.89 | J5: =IFERROR(H5/E5,0) -> 0.031446541 | K5: =(E5-H5)*D5 -> 203396.23 | L5: =E5-H5+K5 -> 3593333.3 | M5: =L5/(1+'Inputs & Summary'!$C$11)^(1-1) -> 3593333.3 | N5: =IF(B5>='Inputs & Summary'!$C$18,'Inputs & Summary'!$C$17*VLOOKUP('Inputs & Summary'!$C$18,'Inputs & Summary'!$H$21:$I$29,2,FALSE)*(1+'Inputs & Summary'!$C$11)^(1-1),0) -> 0 | O5: =H5+N5 -> 110062.89 | P5: =O5/(1+'Inputs & Summary'!$C$11)^(1-1) -> 110062.89
A6: 2 | B6: ='Inputs & Summary'!$C$7+2-1 -> 51 | C6: =IFERROR(VLOOKUP(B6,'Life Expectancy'!$A$6:$B$81,2,FALSE),1.5) -> 31 | D6: ='4% Rule'!C6 -> 0.06 | E6: =MAX(L5,0) -> 3593333.3 | F6: =E6/MAX(C6,1) -> 115913.98 | G6: =MIN('Inputs & Summary'!$C$14*E6,MAX('Inputs & Summary'!$C$13*E6,F6)) -> 115913.98 | H6: =MIN(MIN(H5*(1+'Inputs & Summary'!$C$15),MAX(H5*(1-'Inputs & Summary'!$C$15),G6)),E6) -> 115566.04 | I6: =H6/(1+'Inputs & Summary'!$C$11)^(2-1) -> 112200.04 | J6: =IFERROR(H6/E6,0) -> 0.032161235 | K6: =(E6-H6)*D6 -> 208666.04 | L6: =E6-H6+K6 -> 3686433.3 | M6: =L6/(1+'Inputs & Summary'!$C$11)^(2-1) -> 3579061.5 | N6: =IF(B6>='Inputs & Summary'!$C$18,'Inputs & Summary'!$C$17*VLOOKUP('Inputs & Summary'!$C$18,'Inputs & Summary'!$H$21:$I$29,2,FALSE)*(1+'Inputs & Summary'!$C$11)^(2-1),0) -> 0 | O6: =H6+N6 -> 115566.04 | P6: =O6/(1+'Inputs & Summary'!$C$11)^(2-1) -> 112200.04
A7: 3 | B7: ='Inputs & Summary'!$C$7+3-1 -> 52 | C7: =IFERROR(VLOOKUP(B7,'Life Expectancy'!$A$6:$B$81,2,FALSE),1.5) -> 30.2 | D7: ='4% Rule'!C7 -> 0.06 | E7: =MAX(L6,0) -> 3686433.3 | F7: =E7/MAX(C7,1) -> 122067.33 | G7: =MIN('Inputs & Summary'!$C$14*E7,MAX('Inputs & Summary'!$C$13*E7,F7)) -> 122067.33 | H7: =MIN(MIN(H6*(1+'Inputs & Summary'!$C$15),MAX(H6*(1-'Inputs & Summary'!$C$15),G7)),E7) -> 121344.34 | I7: =H7/(1+'Inputs & Summary'!$C$11)^(3-1) -> 114378.68 | J7: =IFERROR(H7/E7,0) -> 0.032916461 | K7: =(E7-H7)*D7 -> 213905.34 | L7: =E7-H7+K7 -> 3778994.3 | M7: =L7/(1+'Inputs & Summary'!$C$11)^(3-1) -> 3562064.6 | N7: =IF(B7>='Inputs & Summary'!$C$18,'Inputs & Summary'!$C$17*VLOOKUP('Inputs & Summary'!$C$18,'Inputs & Summary'!$H$21:$I$29,2,FALSE)*(1+'Inputs & Summary'!$C$11)^(3-1),0) -> 0 | O7: =H7+N7 -> 121344.34 | P7: =O7/(1+'Inputs & Summary'!$C$11)^(3-1) -> 114378.68
A8: 4 | B8: ='Inputs & Summary'!$C$7+4-1 -> 53 | C8: =IFERROR(VLOOKUP(B8,'Life Expectancy'!$A$6:$B$81,2,FALSE),1.5) -> 29.5 | D8: ='4% Rule'!C8 -> 0.06 | E8: =MAX(L7,0) -> 3778994.3 | F8: =E8/MAX(C8,1) -> 128101.5 | G8: =MIN('Inputs & Summary'!$C$14*E8,MAX('Inputs & Summary'!$C$13*E8,F8)) -> 128101.5 | H8: =MIN(MIN(H7*(1+'Inputs & Summary'!$C$15),MAX(H7*(1-'Inputs & Summary'!$C$15),G8)),E8) -> 127411.56 | I8: =H8/(1+'Inputs & Summary'!$C$11)^(4-1) -> 116599.62 | J8: =IFERROR(H8/E8,0) -> 0.033715731 | K8: =(E8-H8)*D8 -> 219094.97 | L8: =E8-H8+K8 -> 3870677.7 | M8: =L8/(1+'Inputs & Summary'!$C$11)^(4-1) -> 3542218.5 | N8: =IF(B8>='Inputs & Summary'!$C$18,'Inputs & Summary'!$C$17*VLOOKUP('Inputs & Summary'!$C$18,'Inputs & Summary'!$H$21:$I$29,2,FALSE)*(1+'Inputs & Summary'!$C$11)^(4-1),0) -> 0 | O8: =H8+N8 -> 127411.56 | P8: =O8/(1+'Inputs & Summary'!$C$11)^(4-1) -> 116599.62
A9: 5 | B9: ='Inputs & Summary'!$C$7+5-1 -> 54 | C9: =IFERROR(VLOOKUP(B9,'Life Expectancy'!$A$6:$B$81,2,FALSE),1.5) -> 28.7 | D9: ='4% Rule'!C9 -> 0.06 | E9: =MAX(L8,0) -> 3870677.7 | F9: =E9/MAX(C9,1) -> 134866.82 | G9: =MIN('Inputs & Summary'!$C$14*E9,MAX('Inputs & Summary'!$C$13*E9,F9)) -> 134866.82 | H9: =MIN(MIN(H8*(1+'Inputs & Summary'!$C$15),MAX(H8*(1-'Inputs & Summary'!$C$15),G9)),E9) -> 133782.13 | I9: =H9/(1+'Inputs & Summary'!$C$11)^(5-1) -> 118863.69 | J9: =IFERROR(H9/E9,0) -> 0.034562974 | K9: =(E9-H9)*D9 -> 224213.74 | L9: =E9-H9+K9 -> 3961109.3 | M9: =L9/(1+'Inputs & Summary'!$C$11)^(5-1) -> 3519394.3 | N9: =IF(B9>='Inputs & Summary'!$C$18,'Inputs & Summary'!$C$17*VLOOKUP('Inputs & Summary'!$C$18,'Inputs & Summary'!$H$21:$I$29,2,FALSE)*(1+'Inputs & Summary'!$C$11)^(5-1),0) -> 0 | O9: =H9+N9 -> 133782.13 | P9: =O9/(1+'Inputs & Summary'!$C$11)^(5-1) -> 118863.69
A10: 6 | B10: ='Inputs & Summary'!$C$7+6-1 -> 55 | C10: =IFERROR(VLOOKUP(B10,'Life Expectancy'!$A$6:$B$81,2,FALSE),1.5) -> 27.9 | D10: ='4% Rule'!C10 -> 0.06 | E10: =MAX(L9,0) -> 3961109.3 | F10: =E10/MAX(C10,1) -> 141975.25 | G10: =MIN('Inputs & Summary'!$C$14*E10,MAX('Inputs & Summary'!$C$13*E10,F10)) -> 141975.25 | H10: =MIN(MIN(H9*(1+'Inputs & Summary'!$C$15),MAX(H9*(1-'Inputs & Summary'!$C$15),G10)),E10) -> 140471.24 | I10: =H10/(1+'Inputs & Summary'!$C$11)^(6-1) -> 121171.73 | J10: =IFERROR(H10/E10,0) -> 0.035462601 | K10: =(E10-H10)*D10 -> 229238.29 | L10: =E10-H10+K10 -> 4049876.4 | M10: =L10/(1+'Inputs & Summary'!$C$11)^(6-1) -> 3493459 | N10: =IF(B10>='Inputs & Summary'!$C$18,'Inputs & Summary'!$C$17*VLOOKUP('Inputs & Summary'!$C$18,'Inputs & Summary'!$H$21:$I$29,2,FALSE)*(1+'Inputs & Summary'!$C$11)^(6-1),0) -> 0 | O10: =H10+N10 -> 140471.24 | P10: =O10/(1+'Inputs & Summary'!$C$11)^(6-1) -> 121171.73
A11: 7 | B11: ='Inputs & Summary'!$C$7+7-1 -> 56 | C11: =IFERROR(VLOOKUP(B11,'Life Expectancy'!$A$6:$B$81,2,FALSE),1.5) -> 27.1 | D11: ='4% Rule'!C11 -> 0.06 | E11: =MAX(L10,0) -> 4049876.4 | F11: =E11/MAX(C11,1) -> 149441.93 | G11: =MIN('Inputs & Summary'!$C$14*E11,MAX('Inputs & Summary'!$C$13*E11,F11)) -> 149441.93 | H11: =MIN(MIN(H10*(1+'Inputs & Summary'!$C$15),MAX(H10*(1-'Inputs & Summary'!$C$15),G11)),E11) -> 147494.8 | I11: =H11/(1+'Inputs & Summary'!$C$11)^(7-1) -> 123524.58 | J11: =IFERROR(H11/E11,0) -> 0.036419581 | K11: =(E11-H11)*D11 -> 234142.9 | L11: =E11-H11+K11 -> 4136524.5 | M11: =L11/(1+'Inputs & Summary'!$C$11)^(7-1) -> 3464274.1 | N11: =IF(B11>='Inputs & Summary'!$C$18,'Inputs & Summary'!$C$17*VLOOKUP('Inputs & Summary'!$C$18,'Inputs & Summary'!$H$21:$I$29,2,FALSE)*(1+'Inputs & Summary'!$C$11)^(7-1),0) -> 0 | O11: =H11+N11 -> 147494.8 | P11: =O11/(1+'Inputs & Summary'!$C$11)^(7-1) -> 123524.58
A12: 8 | B12: ='Inputs & Summary'!$C$7+8-1 -> 57 | C12: =IFERROR(VLOOKUP(B12,'Life Expectancy'!$A$6:$B$81,2,FALSE),1.5) -> 26.3 | D12: ='4% Rule'!C12 -> 0.06 | E12: =MAX(L11,0) -> 4136524.5 | F12: =E12/MAX(C12,1) -> 157282.3 | G12: =MIN('Inputs & Summary'!$C$14*E12,MAX('Inputs & Summary'!$C$13*E12,F12)) -> 157282.3 | H12: =MIN(MIN(H11*(1+'Inputs & Summary'!$C$15),MAX(H11*(1-'Inputs & Summary'!$C$15),G12)),E12) -> 154869.54 | I12: =H12/(1+'Inputs & Summary'!$C$11)^(8-1) -> 125923.11 | J12: =IFERROR(H12/E12,0) -> 0.037439533 | K12: =(E12-H12)*D12 -> 238899.3 | L12: =E12-H12+K12 -> 4220554.2 | M12: =L12/(1+'Inputs & Summary'!$C$11)^(8-1) -> 3431696.8 | N12: =IF(B12>='Inputs & Summary'!$C$18,'Inputs & Summary'!$C$17*VLOOKUP('Inputs & Summary'!$C$18,'Inputs & Summary'!$H$21:$I$29,2,FALSE)*(1+'Inputs & Summary'!$C$11)^(8-1),0) -> 0 | O12: =H12+N12 -> 154869.54 | P12: =O12/(1+'Inputs & Summary'!$C$11)^(8-1) -> 125923.11
A13: 9 | B13: ='Inputs & Summary'!$C$7+9-1 -> 58 | C13: =IFERROR(VLOOKUP(B13,'Life Expectancy'!$A$6:$B$81,2,FALSE),1.5) -> 25.5 | D13: ='4% Rule'!C13 -> 0.06 | E13: =MAX(L12,0) -> 4220554.2 | F13: =E13/MAX(C13,1) -> 165511.93 | G13: =MIN('Inputs & Summary'!$C$14*E13,MAX('Inputs & Summary'!$C$13*E13,F13)) -> 165511.93 | H13: =MIN(MIN(H12*(1+'Inputs & Summary'!$C$15),MAX(H12*(1-'Inputs & Summary'!$C$15),G13)),E13) -> 162613.02 | I13: =H13/(1+'Inputs & Summary'!$C$11)^(9-1) -> 128368.22 | J13: =IFERROR(H13/E13,0) -> 0.038528831 | K13: =(E13-H13)*D13 -> 243476.47 | L13: =E13-H13+K13 -> 4301417.7 | M13: =L13/(1+'Inputs & Summary'!$C$11)^(9-1) -> 3395578.8 | N13: =IF(B13>='Inputs & Summary'!$C$18,'Inputs & Summary'!$C$17*VLOOKUP('Inputs & Summary'!$C$18,'Inputs & Summary'!$H$21:$I$29,2,FALSE)*(1+'Inputs & Summary'!$C$11)^(9-1),0) -> 0 | O13: =H13+N13 -> 162613.02 | P13: =O13/(1+'Inputs & Summary'!$C$11)^(9-1) -> 128368.22
A14: 10 | B14: ='Inputs & Summary'!$C$7+10-1 -> 59 | C14: =IFERROR(VLOOKUP(B14,'Life Expectancy'!$A$6:$B$81,2,FALSE),1.5) -> 24.8 | D14: ='4% Rule'!C14 -> 0.06 | E14: =MAX(L13,0) -> 4301417.7 | F14: =E14/MAX(C14,1) -> 173444.26 | G14: =MIN('Inputs & Summary'!$C$14*E14,MAX('Inputs & Summary'!$C$13*E14,F14)) -> 173444.26 | H14: =MIN(MIN(H13*(1+'Inputs & Summary'!$C$15),MAX(H13*(1-'Inputs & Summary'!$C$15),G14)),E14) -> 170743.67 | I14: =H14/(1+'Inputs & Summary'!$C$11)^(10-1) -> 130860.81 | J14: =IFERROR(H14/E14,0) -> 0.039694743 | K14: =(E14-H14)*D14 -> 247840.44 | L14: =E14-H14+K14 -> 4378514.5 | M14: =L14/(1+'Inputs & Summary'!$C$11)^(10-1) -> 3355766.7 | N14: =IF(B14>='Inputs & Summary'!$C$18,'Inputs & Summary'!$C$17*VLOOKUP('Inputs & Summary'!$C$18,'Inputs & Summary'!$H$21:$I$29,2,FALSE)*(1+'Inputs & Summary'!$C$11)^(10-1),0) -> 0 | O14: =H14+N14 -> 170743.67 | P14: =O14/(1+'Inputs & Summary'!$C$11)^(10-1) -> 130860.81
A15: 11 | B15: ='Inputs & Summary'!$C$7+11-1 -> 60 | C15: =IFERROR(VLOOKUP(B15,'Life Expectancy'!$A$6:$B$81,2,FALSE),1.5) -> 24 | D15: ='4% Rule'!C15 -> 0.06 | E15: =MAX(L14,0) -> 4378514.5 | F15: =E15/MAX(C15,1) -> 182438.1 | G15: =MIN('Inputs & Summary'!$C$14*E15,MAX('Inputs & Summary'!$C$13*E15,F15)) -> 182438.1 | H15: =MIN(MIN(H14*(1+'Inputs & Summary'!$C$15),MAX(H14*(1-'Inputs & Summary'!$C$15),G15)),E15) -> 179280.86 | I15: =H15/(1+'Inputs & Summary'!$C$11)^(11-1) -> 133401.79 | J15: =IFERROR(H15/E15,0) -> 0.040945589 | K15: =(E15-H15)*D15 -> 251954.02 | L15: =E15-H15+K15 -> 4451187.6 | M15: =L15/(1+'Inputs & Summary'!$C$11)^(11-1) -> 3312101.6 | N15: =IF(B15>='Inputs & Summary'!$C$18,'Inputs & Summary'!$C$17*VLOOKUP('Inputs & Summary'!$C$18,'Inputs & Summary'!$H$21:$I$29,2,FALSE)*(1+'Inputs & Summary'!$C$11)^(11-1),0) -> 0 | O15: =H15+N15 -> 179280.86 | P15: =O15/(1+'Inputs & Summary'!$C$11)^(11-1) -> 133401.79
A16: 12 | B16: ='Inputs & Summary'!$C$7+12-1 -> 61 | C16: =IFERROR(VLOOKUP(B16,'Life Expectancy'!$A$6:$B$81,2,FALSE),1.5) -> 23.2 | D16: ='4% Rule'!C16 -> 0.06 | E16: =MAX(L15,0) -> 4451187.6 | F16: =E16/MAX(C16,1) -> 191861.54 | G16: =MIN('Inputs & Summary'!$C$14*E16,MAX('Inputs & Summary'!$C$13*E16,F16)) -> 191861.54 | H16: =MIN(MIN(H15*(1+'Inputs & Summary'!$C$15),MAX(H15*(1-'Inputs & Summary'!$C$15),G16)),E16) -> 188244.9 | I16: =H16/(1+'Inputs & Summary'!$C$11)^(12-1) -> 135992.12 | J16: =IFERROR(H16/E16,0) -> 0.042290938 | K16: =(E16-H16)*D16 -> 255776.56 | L16: =E16-H16+K16 -> 4518719.3 | M16: =L16/(1+'Inputs & Summary'!$C$11)^(12-1) -> 3264419 | N16: =IF(B16>='Inputs & Summary'!$C$18,'Inputs & Summary'!$C$17*VLOOKUP('Inputs & Summary'!$C$18,'Inputs & Summary'!$H$21:$I$29,2,FALSE)*(1+'Inputs & Summary'!$C$11)^(12-1),0) -> 0 | O16: =H16+N16 -> 188244.9 | P16: =O16/(1+'Inputs & Summary'!$C$11)^(12-1) -> 135992.12
A17: 13 | B17: ='Inputs & Summary'!$C$7+13-1 -> 62 | C17: =IFERROR(VLOOKUP(B17,'Life Expectancy'!$A$6:$B$81,2,FALSE),1.5) -> 22.4 | D17: ='4% Rule'!C17 -> 0.06 | E17: =MAX(L16,0) -> 4518719.3 | F17: =E17/MAX(C17,1) -> 201728.54 | G17: =MIN('Inputs & Summary'!$C$14*E17,MAX('Inputs & Summary'!$C$13*E17,F17)) -> 201728.54 | H17: =MIN(MIN(H16*(1+'Inputs & Summary'!$C$15),MAX(H16*(1-'Inputs & Summary'!$C$15),G17)),E17) -> 197657.14 | I17: =H17/(1+'Inputs & Summary'!$C$11)^(13-1) -> 138632.74 | J17: =IFERROR(H17/E17,0) -> 0.04374185 | K17: =(E17-H17)*D17 -> 259263.73 | L17: =E17-H17+K17 -> 4580325.9 | M17: =L17/(1+'Inputs & Summary'!$C$11)^(13-1) -> 3212548.4 | N17: =IF(B17>='Inputs & Summary'!$C$18,'Inputs & Summary'!$C$17*VLOOKUP('Inputs & Summary'!$C$18,'Inputs & Summary'!$H$21:$I$29,2,FALSE)*(1+'Inputs & Summary'!$C$11)^(13-1),0) -> 0 | O17: =H17+N17 -> 197657.14 | P17: =O17/(1+'Inputs & Summary'!$C$11)^(13-1) -> 138632.74
A18: 14 | B18: ='Inputs & Summary'!$C$7+14-1 -> 63 | C18: =IFERROR(VLOOKUP(B18,'Life Expectancy'!$A$6:$B$81,2,FALSE),1.5) -> 21.7 | D18: ='4% Rule'!C18 -> 0.06 | E18: =MAX(L17,0) -> 4580325.9 | F18: =E18/MAX(C18,1) -> 211074.92 | G18: =MIN('Inputs & Summary'!$C$14*E18,MAX('Inputs & Summary'!$C$13*E18,F18)) -> 211074.92 | H18: =MIN(MIN(H17*(1+'Inputs & Summary'!$C$15),MAX(H17*(1-'Inputs & Summary'!$C$15),G18)),E18) -> 207540 | I18: =H18/(1+'Inputs & Summary'!$C$11)^(14-1) -> 141324.64 | J18: =IFERROR(H18/E18,0) -> 0.045311187 | K18: =(E18-H18)*D18 -> 262367.15 | L18: =E18-H18+K18 -> 4635153 | M18: =L18/(1+'Inputs & Summary'!$C$11)^(14-1) -> 3156313.7 | N18: =IF(B18>='Inputs & Summary'!$C$18,'Inputs & Summary'!$C$17*VLOOKUP('Inputs & Summary'!$C$18,'Inputs & Summary'!$H$21:$I$29,2,FALSE)*(1+'Inputs & Summary'!$C$11)^(14-1),0) -> 0 | O18: =H18+N18 -> 207540 | P18: =O18/(1+'Inputs & Summary'!$C$11)^(14-1) -> 141324.64
A19: 15 | B19: ='Inputs & Summary'!$C$7+15-1 -> 64 | C19: =IFERROR(VLOOKUP(B19,'Life Expectancy'!$A$6:$B$81,2,FALSE),1.5) -> 21 | D19: ='4% Rule'!C19 -> 0.06 | E19: =MAX(L18,0) -> 4635153 | F19: =E19/MAX(C19,1) -> 220721.57 | G19: =MIN('Inputs & Summary'!$C$14*E19,MAX('Inputs & Summary'!$C$13*E19,F19)) -> 220721.57 | H19: =MIN(MIN(H18*(1+'Inputs & Summary'!$C$15),MAX(H18*(1-'Inputs & Summary'!$C$15),G19)),E19) -> 217917 | I19: =H19/(1+'Inputs & Summary'!$C$11)^(15-1) -> 144068.81 | J19: =IFERROR(H19/E19,0) -> 0.047013982 | K19: =(E19-H19)*D19 -> 265034.16 | L19: =E19-H19+K19 -> 4682270.2 | M19: =L19/(1+'Inputs & Summary'!$C$11)^(15-1) -> 3095532.2 | N19: =IF(B19>='Inputs & Summary'!$C$18,'Inputs & Summary'!$C$17*VLOOKUP('Inputs & Summary'!$C$18,'Inputs & Summary'!$H$21:$I$29,2,FALSE)*(1+'Inputs & Summary'!$C$11)^(15-1),0) -> 0 | O19: =H19+N19 -> 217917 | P19: =O19/(1+'Inputs & Summary'!$C$11)^(15-1) -> 144068.81
A20: 16 | B20: ='Inputs & Summary'!$C$7+16-1 -> 65 | C20: =IFERROR(VLOOKUP(B20,'Life Expectancy'!$A$6:$B$81,2,FALSE),1.5) -> 20.2 | D20: ='4% Rule'!C20 -> 0.06 | E20: =MAX(L19,0) -> 4682270.2 | F20: =E20/MAX(C20,1) -> 231795.55 | G20: =MIN('Inputs & Summary'!$C$14*E20,MAX('Inputs & Summary'!$C$13*E20,F20)) -> 231795.55 | H20: =MIN(MIN(H19*(1+'Inputs & Summary'!$C$15),MAX(H19*(1-'Inputs & Summary'!$C$15),G20)),E20) -> 228812.85 | I20: =H20/(1+'Inputs & Summary'!$C$11)^(16-1) -> 146866.26 | J20: =IFERROR(H20/E20,0) -> 0.04886793 | K20: =(E20-H20)*D20 -> 267207.44 | L20: =E20-H20+K20 -> 4720664.8 | M20: =L20/(1+'Inputs & Summary'!$C$11)^(16-1) -> 3030015.1 | N20: =IF(B20>='Inputs & Summary'!$C$18,'Inputs & Summary'!$C$17*VLOOKUP('Inputs & Summary'!$C$18,'Inputs & Summary'!$H$21:$I$29,2,FALSE)*(1+'Inputs & Summary'!$C$11)^(16-1),0) -> 0 | O20: =H20+N20 -> 228812.85 | P20: =O20/(1+'Inputs & Summary'!$C$11)^(16-1) -> 146866.26
A21: 17 | B21: ='Inputs & Summary'!$C$7+17-1 -> 66 | C21: =IFERROR(VLOOKUP(B21,'Life Expectancy'!$A$6:$B$81,2,FALSE),1.5) -> 19.5 | D21: ='4% Rule'!C21 -> 0.06 | E21: =MAX(L20,0) -> 4720664.8 | F21: =E21/MAX(C21,1) -> 242085.37 | G21: =MIN('Inputs & Summary'!$C$14*E21,MAX('Inputs & Summary'!$C$13*E21,F21)) -> 242085.37 | H21: =MIN(MIN(H20*(1+'Inputs & Summary'!$C$15),MAX(H20*(1-'Inputs & Summary'!$C$15),G21)),E21) -> 240253.49 | I21: =H21/(1+'Inputs & Summary'!$C$11)^(17-1) -> 149718.03 | J21: =IFERROR(H21/E21,0) -> 0.050893996 | K21: =(E21-H21)*D21 -> 268824.68 | L21: =E21-H21+K21 -> 4749236 | M21: =L21/(1+'Inputs & Summary'!$C$11)^(17-1) -> 2959566.8 | N21: =IF(B21>='Inputs & Summary'!$C$18,'Inputs & Summary'!$C$17*VLOOKUP('Inputs & Summary'!$C$18,'Inputs & Summary'!$H$21:$I$29,2,FALSE)*(1+'Inputs & Summary'!$C$11)^(17-1),0) -> 0 | O21: =H21+N21 -> 240253.49 | P21: =O21/(1+'Inputs & Summary'!$C$11)^(17-1) -> 149718.03
A22: 18 | B22: ='Inputs & Summary'!$C$7+18-1 -> 67 | C22: =IFERROR(VLOOKUP(B22,'Life Expectancy'!$A$6:$B$81,2,FALSE),1.5) -> 18.8 | D22: ='4% Rule'!C22 -> 0.06 | E22: =MAX(L21,0) -> 4749236 | F22: =E22/MAX(C22,1) -> 252618.93 | G22: =MIN('Inputs & Summary'!$C$14*E22,MAX('Inputs & Summary'!$C$13*E22,F22)) -> 252618.93 | H22: =MIN(MIN(H21*(1+'Inputs & Summary'!$C$15),MAX(H21*(1-'Inputs & Summary'!$C$15),G22)),E22) -> 252266.17 | I22: =H22/(1+'Inputs & Summary'!$C$11)^(18-1) -> 152625.18 | J22: =IFERROR(H22/E22,0) -> 0.053117211 | K22: =(E22-H22)*D22 -> 269818.19 | L22: =E22-H22+K22 -> 4766788 | M22: =L22/(1+'Inputs & Summary'!$C$11)^(18-1) -> 2883985.1 | N22: =IF(B22>='Inputs & Summary'!$C$18,'Inputs & Summary'!$C$17*VLOOKUP('Inputs & Summary'!$C$18,'Inputs & Summary'!$H$21:$I$29,2,FALSE)*(1+'Inputs & Summary'!$C$11)^(18-1),0) -> 49585.429 | O22: =H22+N22 -> 301851.6 | P22: =O22/(1+'Inputs & Summary'!$C$11)^(18-1) -> 182625.18
A23: 19 | B23: ='Inputs & Summary'!$C$7+19-1 -> 68 | C23: =IFERROR(VLOOKUP(B23,'Life Expectancy'!$A$6:$B$81,2,FALSE),1.5) -> 18.1 | D23: ='4% Rule'!C23 -> 0.06 | E23: =MAX(L22,0) -> 4766788 | F23: =E23/MAX(C23,1) -> 263358.45 | G23: =MIN('Inputs & Summary'!$C$14*E23,MAX('Inputs & Summary'!$C$13*E23,F23)) -> 263358.45 | H23: =MIN(MIN(H22*(1+'Inputs & Summary'!$C$15),MAX(H22*(1-'Inputs & Summary'!$C$15),G23)),E23) -> 263358.45 | I23: =H23/(1+'Inputs & Summary'!$C$11)^(19-1) -> 154695.33 | J23: =IFERROR(H23/E23,0) -> 0.055248619 | K23: =(E23-H23)*D23 -> 270205.77 | L23: =E23-H23+K23 -> 4773635.3 | M23: =L23/(1+'Inputs & Summary'!$C$11)^(19-1) -> 2804007.6 | N23: =IF(B23>='Inputs & Summary'!$C$18,'Inputs & Summary'!$C$17*VLOOKUP('Inputs & Summary'!$C$18,'Inputs & Summary'!$H$21:$I$29,2,FALSE)*(1+'Inputs & Summary'!$C$11)^(19-1),0) -> 51072.992 | O23: =H23+N23 -> 314431.44 | P23: =O23/(1+'Inputs & Summary'!$C$11)^(19-1) -> 184695.33
A24: 20 | B24: ='Inputs & Summary'!$C$7+20-1 -> 69 | C24: =IFERROR(VLOOKUP(B24,'Life Expectancy'!$A$6:$B$81,2,FALSE),1.5) -> 17.4 | D24: ='4% Rule'!C24 -> 0.06 | E24: =MAX(L23,0) -> 4773635.3 | F24: =E24/MAX(C24,1) -> 274346.86 | G24: =MIN('Inputs & Summary'!$C$14*E24,MAX('Inputs & Summary'!$C$13*E24,F24)) -> 274346.86 | H24: =MIN(MIN(H23*(1+'Inputs & Summary'!$C$15),MAX(H23*(1-'Inputs & Summary'!$C$15),G24)),E24) -> 274346.86 | I24: =H24/(1+'Inputs & Summary'!$C$11)^(20-1) -> 156456.18 | J24: =IFERROR(H24/E24,0) -> 0.057471264 | K24: =(E24-H24)*D24 -> 269957.31 | L24: =E24-H24+K24 -> 4769245.7 | M24: =L24/(1+'Inputs & Summary'!$C$11)^(20-1) -> 2719834.2 | N24: =IF(B24>='Inputs & Summary'!$C$18,'Inputs & Summary'!$C$17*VLOOKUP('Inputs & Summary'!$C$18,'Inputs & Summary'!$H$21:$I$29,2,FALSE)*(1+'Inputs & Summary'!$C$11)^(20-1),0) -> 52605.182 | O24: =H24+N24 -> 326952.04 | P24: =O24/(1+'Inputs & Summary'!$C$11)^(20-1) -> 186456.18
A25: 21 | B25: ='Inputs & Summary'!$C$7+21-1 -> 70 | C25: =IFERROR(VLOOKUP(B25,'Life Expectancy'!$A$6:$B$81,2,FALSE),1.5) -> 16.7 | D25: ='4% Rule'!C25 -> 0.06 | E25: =MAX(L24,0) -> 4769245.7 | F25: =E25/MAX(C25,1) -> 285583.58 | G25: =MIN('Inputs & Summary'!$C$14*E25,MAX('Inputs & Summary'!$C$13*E25,F25)) -> 285583.58 | H25: =MIN(MIN(H24*(1+'Inputs & Summary'!$C$15),MAX(H24*(1-'Inputs & Summary'!$C$15),G25)),E25) -> 285583.58 | I25: =H25/(1+'Inputs & Summary'!$C$11)^(21-1) -> 158120.7 | J25: =IFERROR(H25/E25,0) -> 0.05988024 | K25: =(E25-H25)*D25 -> 269019.73 | L25: =E25-H25+K25 -> 4752681.9 | M25: =L25/(1+'Inputs & Summary'!$C$11)^(21-1) -> 2631444.7 | N25: =IF(B25>='Inputs & Summary'!$C$18,'Inputs & Summary'!$C$17*VLOOKUP('Inputs & Summary'!$C$18,'Inputs & Summary'!$H$21:$I$29,2,FALSE)*(1+'Inputs & Summary'!$C$11)^(21-1),0) -> 54183.337 | O25: =H25+N25 -> 339766.91 | P25: =O25/(1+'Inputs & Summary'!$C$11)^(21-1) -> 188120.7
A26: 22 | B26: ='Inputs & Summary'!$C$7+22-1 -> 71 | C26: =IFERROR(VLOOKUP(B26,'Life Expectancy'!$A$6:$B$81,2,FALSE),1.5) -> 16 | D26: ='4% Rule'!C26 -> 0.06 | E26: =MAX(L25,0) -> 4752681.9 | F26: =E26/MAX(C26,1) -> 297042.62 | G26: =MIN('Inputs & Summary'!$C$14*E26,MAX('Inputs & Summary'!$C$13*E26,F26)) -> 285160.91 | H26: =MIN(MIN(H25*(1+'Inputs & Summary'!$C$15),MAX(H25*(1-'Inputs & Summary'!$C$15),G26)),E26) -> 285160.91 | I26: =H26/(1+'Inputs & Summary'!$C$11)^(22-1) -> 153288.04 | J26: =IFERROR(H26/E26,0) -> 0.06 | K26: =(E26-H26)*D26 -> 268051.26 | L26: =E26-H26+K26 -> 4735572.2 | M26: =L26/(1+'Inputs & Summary'!$C$11)^(22-1) -> 2545603.4 | N26: =IF(B26>='Inputs & Summary'!$C$18,'Inputs & Summary'!$C$17*VLOOKUP('Inputs & Summary'!$C$18,'Inputs & Summary'!$H$21:$I$29,2,FALSE)*(1+'Inputs & Summary'!$C$11)^(22-1),0) -> 55808.837 | O26: =H26+N26 -> 340969.75 | P26: =O26/(1+'Inputs & Summary'!$C$11)^(22-1) -> 183288.04
A27: 23 | B27: ='Inputs & Summary'!$C$7+23-1 -> 72 | C27: =IFERROR(VLOOKUP(B27,'Life Expectancy'!$A$6:$B$81,2,FALSE),1.5) -> 15.4 | D27: ='4% Rule'!C27 -> 0.06 | E27: =MAX(L26,0) -> 4735572.2 | F27: =E27/MAX(C27,1) -> 307504.69 | G27: =MIN('Inputs & Summary'!$C$14*E27,MAX('Inputs & Summary'!$C$13*E27,F27)) -> 284134.33 | H27: =MIN(MIN(H26*(1+'Inputs & Summary'!$C$15),MAX(H26*(1-'Inputs & Summary'!$C$15),G27)),E27) -> 284134.33 | I27: =H27/(1+'Inputs & Summary'!$C$11)^(23-1) -> 148287.58 | J27: =IFERROR(H27/E27,0) -> 0.06 | K27: =(E27-H27)*D27 -> 267086.27 | L27: =E27-H27+K27 -> 4718524.2 | M27: =L27/(1+'Inputs & Summary'!$C$11)^(23-1) -> 2462562.4 | N27: =IF(B27>='Inputs & Summary'!$C$18,'Inputs & Summary'!$C$17*VLOOKUP('Inputs & Summary'!$C$18,'Inputs & Summary'!$H$21:$I$29,2,FALSE)*(1+'Inputs & Summary'!$C$11)^(23-1),0) -> 57483.102 | O27: =H27+N27 -> 341617.44 | P27: =O27/(1+'Inputs & Summary'!$C$11)^(23-1) -> 178287.58
A28: 24 | B28: ='Inputs & Summary'!$C$7+24-1 -> 73 | C28: =IFERROR(VLOOKUP(B28,'Life Expectancy'!$A$6:$B$81,2,FALSE),1.5) -> 14.7 | D28: ='4% Rule'!C28 -> 0.06 | E28: =MAX(L27,0) -> 4718524.2 | F28: =E28/MAX(C28,1) -> 320988.04 | G28: =MIN('Inputs & Summary'!$C$14*E28,MAX('Inputs & Summary'!$C$13*E28,F28)) -> 283111.45 | H28: =MIN(MIN(H27*(1+'Inputs & Summary'!$C$15),MAX(H27*(1-'Inputs & Summary'!$C$15),G28)),E28) -> 283111.45 | I28: =H28/(1+'Inputs & Summary'!$C$11)^(24-1) -> 143450.24 | J28: =IFERROR(H28/E28,0) -> 0.06 | K28: =(E28-H28)*D28 -> 266124.76 | L28: =E28-H28+K28 -> 4701537.5 | M28: =L28/(1+'Inputs & Summary'!$C$11)^(24-1) -> 2382230.3 | N28: =IF(B28>='Inputs & Summary'!$C$18,'Inputs & Summary'!$C$17*VLOOKUP('Inputs & Summary'!$C$18,'Inputs & Summary'!$H$21:$I$29,2,FALSE)*(1+'Inputs & Summary'!$C$11)^(24-1),0) -> 59207.595 | O28: =H28+N28 -> 342319.05 | P28: =O28/(1+'Inputs & Summary'!$C$11)^(24-1) -> 173450.24
A29: 25 | B29: ='Inputs & Summary'!$C$7+25-1 -> 74 | C29: =IFERROR(VLOOKUP(B29,'Life Expectancy'!$A$6:$B$81,2,FALSE),1.5) -> 14.1 | D29: ='4% Rule'!C29 -> 0.06 | E29: =MAX(L28,0) -> 4701537.5 | F29: =E29/MAX(C29,1) -> 333442.38 | G29: =MIN('Inputs & Summary'!$C$14*E29,MAX('Inputs & Summary'!$C$13*E29,F29)) -> 282092.25 | H29: =MIN(MIN(H28*(1+'Inputs & Summary'!$C$15),MAX(H28*(1-'Inputs & Summary'!$C$15),G29)),E29) -> 282092.25 | I29: =H29/(1+'Inputs & Summary'!$C$11)^(25-1) -> 138770.69 | J29: =IFERROR(H29/E29,0) -> 0.06 | K29: =(E29-H29)*D29 -> 265166.71 | L29: =E29-H29+K29 -> 4684612 | M29: =L29/(1+'Inputs & Summary'!$C$11)^(25-1) -> 2304518.7 | N29: =IF(B29>='Inputs & Summary'!$C$18,'Inputs & Summary'!$C$17*VLOOKUP('Inputs & Summary'!$C$18,'Inputs & Summary'!$H$21:$I$29,2,FALSE)*(1+'Inputs & Summary'!$C$11)^(25-1),0) -> 60983.823 | O29: =H29+N29 -> 343076.07 | P29: =O29/(1+'Inputs & Summary'!$C$11)^(25-1) -> 168770.69
A30: 26 | B30: ='Inputs & Summary'!$C$7+26-1 -> 75 | C30: =IFERROR(VLOOKUP(B30,'Life Expectancy'!$A$6:$B$81,2,FALSE),1.5) -> 13.4 | D30: ='4% Rule'!C30 -> 0.06 | E30: =MAX(L29,0) -> 4684612 | F30: =E30/MAX(C30,1) -> 349597.91 | G30: =MIN('Inputs & Summary'!$C$14*E30,MAX('Inputs & Summary'!$C$13*E30,F30)) -> 281076.72 | H30: =MIN(MIN(H29*(1+'Inputs & Summary'!$C$15),MAX(H29*(1-'Inputs & Summary'!$C$15),G30)),E30) -> 281076.72 | I30: =H30/(1+'Inputs & Summary'!$C$11)^(26-1) -> 134243.81 | J30: =IFERROR(H30/E30,0) -> 0.06 | K30: =(E30-H30)*D30 -> 264212.11 | L30: =E30-H30+K30 -> 4667747.4 | M30: =L30/(1+'Inputs & Summary'!$C$11)^(26-1) -> 2229342.1 | N30: =IF(B30>='Inputs & Summary'!$C$18,'Inputs & Summary'!$C$17*VLOOKUP('Inputs & Summary'!$C$18,'Inputs & Summary'!$H$21:$I$29,2,FALSE)*(1+'Inputs & Summary'!$C$11)^(26-1),0) -> 62813.338 | O30: =H30+N30 -> 343890.06 | P30: =O30/(1+'Inputs & Summary'!$C$11)^(26-1) -> 164243.81
A31: 27 | B31: ='Inputs & Summary'!$C$7+27-1 -> 76 | C31: =IFERROR(VLOOKUP(B31,'Life Expectancy'!$A$6:$B$81,2,FALSE),1.5) -> 12.8 | D31: ='4% Rule'!C31 -> 0.06 | E31: =MAX(L30,0) -> 4667747.4 | F31: =E31/MAX(C31,1) -> 364667.76 | G31: =MIN('Inputs & Summary'!$C$14*E31,MAX('Inputs & Summary'!$C$13*E31,F31)) -> 280064.84 | H31: =MIN(MIN(H30*(1+'Inputs & Summary'!$C$15),MAX(H30*(1-'Inputs & Summary'!$C$15),G31)),E31) -> 280064.84 | I31: =H31/(1+'Inputs & Summary'!$C$11)^(27-1) -> 129864.59 | J31: =IFERROR(H31/E31,0) -> 0.06 | K31: =(E31-H31)*D31 -> 263260.95 | L31: =E31-H31+K31 -> 4650943.5 | M31: =L31/(1+'Inputs & Summary'!$C$11)^(27-1) -> 2156618 | N31: =IF(B31>='Inputs & Summary'!$C$18,'Inputs & Summary'!$C$17*VLOOKUP('Inputs & Summary'!$C$18,'Inputs & Summary'!$H$21:$I$29,2,FALSE)*(1+'Inputs & Summary'!$C$11)^(27-1),0) -> 64697.738 | O31: =H31+N31 -> 344762.58 | P31: =O31/(1+'Inputs & Summary'!$C$11)^(27-1) -> 159864.59
A32: 28 | B32: ='Inputs & Summary'!$C$7+28-1 -> 77 | C32: =IFERROR(VLOOKUP(B32,'Life Expectancy'!$A$6:$B$81,2,FALSE),1.5) -> 12.2 | D32: ='4% Rule'!C32 -> 0.06 | E32: =MAX(L31,0) -> 4650943.5 | F32: =E32/MAX(C32,1) -> 381224.87 | G32: =MIN('Inputs & Summary'!$C$14*E32,MAX('Inputs & Summary'!$C$13*E32,F32)) -> 279056.61 | H32: =MIN(MIN(H31*(1+'Inputs & Summary'!$C$15),MAX(H31*(1-'Inputs & Summary'!$C$15),G32)),E32) -> 279056.61 | I32: =H32/(1+'Inputs & Summary'!$C$11)^(28-1) -> 125628.23 | J32: =IFERROR(H32/E32,0) -> 0.06 | K32: =(E32-H32)*D32 -> 262313.21 | L32: =E32-H32+K32 -> 4634200.1 | M32: =L32/(1+'Inputs & Summary'!$C$11)^(28-1) -> 2086266.2 | N32: =IF(B32>='Inputs & Summary'!$C$18,'Inputs & Summary'!$C$17*VLOOKUP('Inputs & Summary'!$C$18,'Inputs & Summary'!$H$21:$I$29,2,FALSE)*(1+'Inputs & Summary'!$C$11)^(28-1),0) -> 66638.67 | O32: =H32+N32 -> 345695.28 | P32: =O32/(1+'Inputs & Summary'!$C$11)^(28-1) -> 155628.23
A33: 29 | B33: ='Inputs & Summary'!$C$7+29-1 -> 78 | C33: =IFERROR(VLOOKUP(B33,'Life Expectancy'!$A$6:$B$81,2,FALSE),1.5) -> 11.6 | D33: ='4% Rule'!C33 -> 0.06 | E33: =MAX(L32,0) -> 4634200.1 | F33: =E33/MAX(C33,1) -> 399500.01 | G33: =MIN('Inputs & Summary'!$C$14*E33,MAX('Inputs & Summary'!$C$13*E33,F33)) -> 278052 | H33: =MIN(MIN(H32*(1+'Inputs & Summary'!$C$15),MAX(H32*(1-'Inputs & Summary'!$C$15),G33)),E33) -> 278052 | I33: =H33/(1+'Inputs & Summary'!$C$11)^(29-1) -> 121530.07 | J33: =IFERROR(H33/E33,0) -> 0.06 | K33: =(E33-H33)*D33 -> 261368.88 | L33: =E33-H33+K33 -> 4617517 | M33: =L33/(1+'Inputs & Summary'!$C$11)^(29-1) -> 2018209.3 | N33: =IF(B33>='Inputs & Summary'!$C$18,'Inputs & Summary'!$C$17*VLOOKUP('Inputs & Summary'!$C$18,'Inputs & Summary'!$H$21:$I$29,2,FALSE)*(1+'Inputs & Summary'!$C$11)^(29-1),0) -> 68637.83 | O33: =H33+N33 -> 346689.83 | P33: =O33/(1+'Inputs & Summary'!$C$11)^(29-1) -> 151530.07
A34: 30 | B34: ='Inputs & Summary'!$C$7+30-1 -> 79 | C34: =IFERROR(VLOOKUP(B34,'Life Expectancy'!$A$6:$B$81,2,FALSE),1.5) -> 11 | D34: ='4% Rule'!C34 -> 0.06 | E34: =MAX(L33,0) -> 4617517 | F34: =E34/MAX(C34,1) -> 419774.27 | G34: =MIN('Inputs & Summary'!$C$14*E34,MAX('Inputs & Summary'!$C$13*E34,F34)) -> 277051.02 | H34: =MIN(MIN(H33*(1+'Inputs & Summary'!$C$15),MAX(H33*(1-'Inputs & Summary'!$C$15),G34)),E34) -> 277051.02 | I34: =H34/(1+'Inputs & Summary'!$C$11)^(30-1) -> 117565.59 | J34: =IFERROR(H34/E34,0) -> 0.06 | K34: =(E34-H34)*D34 -> 260427.96 | L34: =E34-H34+K34 -> 4600893.9 | M34: =L34/(1+'Inputs & Summary'!$C$11)^(30-1) -> 1952372.6 | N34: =IF(B34>='Inputs & Summary'!$C$18,'Inputs & Summary'!$C$17*VLOOKUP('Inputs & Summary'!$C$18,'Inputs & Summary'!$H$21:$I$29,2,FALSE)*(1+'Inputs & Summary'!$C$11)^(30-1),0) -> 70696.965 | O34: =H34+N34 -> 347747.98 | P34: =O34/(1+'Inputs & Summary'!$C$11)^(30-1) -> 147565.59
A35: 31 | B35: ='Inputs & Summary'!$C$7+31-1 -> 80 | C35: =IFERROR(VLOOKUP(B35,'Life Expectancy'!$A$6:$B$81,2,FALSE),1.5) -> 10.4 | D35: ='4% Rule'!C35 -> 0.06 | E35: =MAX(L34,0) -> 4600893.9 | F35: =E35/MAX(C35,1) -> 442393.64 | G35: =MIN('Inputs & Summary'!$C$14*E35,MAX('Inputs & Summary'!$C$13*E35,F35)) -> 276053.63 | H35: =MIN(MIN(H34*(1+'Inputs & Summary'!$C$15),MAX(H34*(1-'Inputs & Summary'!$C$15),G35)),E35) -> 276053.63 | I35: =H35/(1+'Inputs & Summary'!$C$11)^(31-1) -> 113730.44 | J35: =IFERROR(H35/E35,0) -> 0.06 | K35: =(E35-H35)*D35 -> 259490.42 | L35: =E35-H35+K35 -> 4584330.7 | M35: =L35/(1+'Inputs & Summary'!$C$11)^(31-1) -> 1888683.5 | N35: =IF(B35>='Inputs & Summary'!$C$18,'Inputs & Summary'!$C$17*VLOOKUP('Inputs & Summary'!$C$18,'Inputs & Summary'!$H$21:$I$29,2,FALSE)*(1+'Inputs & Summary'!$C$11)^(31-1),0) -> 72817.874 | O35: =H35+N35 -> 348871.51 | P35: =O35/(1+'Inputs & Summary'!$C$11)^(31-1) -> 143730.44
A36: 32 | B36: ='Inputs & Summary'!$C$7+32-1 -> 81 | C36: =IFERROR(VLOOKUP(B36,'Life Expectancy'!$A$6:$B$81,2,FALSE),1.5) -> 9.9 | D36: ='4% Rule'!C36 -> 0.06 | E36: =MAX(L35,0) -> 4584330.7 | F36: =E36/MAX(C36,1) -> 463063.7 | G36: =MIN('Inputs & Summary'!$C$14*E36,MAX('Inputs & Summary'!$C$13*E36,F36)) -> 275059.84 | H36: =MIN(MIN(H35*(1+'Inputs & Summary'!$C$15),MAX(H35*(1-'Inputs & Summary'!$C$15),G36)),E36) -> 275059.84 | I36: =H36/(1+'Inputs & Summary'!$C$11)^(32-1) -> 110020.4 | J36: =IFERROR(H36/E36,0) -> 0.06 | K36: =(E36-H36)*D36 -> 258556.25 | L36: =E36-H36+K36 -> 4567827.1 | M36: =L36/(1+'Inputs & Summary'!$C$11)^(32-1) -> 1827072.1 | N36: =IF(B36>='Inputs & Summary'!$C$18,'Inputs & Summary'!$C$17*VLOOKUP('Inputs & Summary'!$C$18,'Inputs & Summary'!$H$21:$I$29,2,FALSE)*(1+'Inputs & Summary'!$C$11)^(32-1),0) -> 75002.41 | O36: =H36+N36 -> 350062.25 | P36: =O36/(1+'Inputs & Summary'!$C$11)^(32-1) -> 140020.4
A37: 33 | B37: ='Inputs & Summary'!$C$7+33-1 -> 82 | C37: =IFERROR(VLOOKUP(B37,'Life Expectancy'!$A$6:$B$81,2,FALSE),1.5) -> 9.4 | D37: ='4% Rule'!C37 -> 0.06 | E37: =MAX(L36,0) -> 4567827.1 | F37: =E37/MAX(C37,1) -> 485939.05 | G37: =MIN('Inputs & Summary'!$C$14*E37,MAX('Inputs & Summary'!$C$13*E37,F37)) -> 274069.63 | H37: =MIN(MIN(H36*(1+'Inputs & Summary'!$C$15),MAX(H36*(1-'Inputs & Summary'!$C$15),G37)),E37) -> 274069.63 | I37: =H37/(1+'Inputs & Summary'!$C$11)^(33-1) -> 106431.39 | J37: =IFERROR(H37/E37,0) -> 0.06 | K37: =(E37-H37)*D37 -> 257625.45 | L37: =E37-H37+K37 -> 4551382.9 | M37: =L37/(1+'Inputs & Summary'!$C$11)^(33-1) -> 1767470.5 | N37: =IF(B37>='Inputs & Summary'!$C$18,'Inputs & Summary'!$C$17*VLOOKUP('Inputs & Summary'!$C$18,'Inputs & Summary'!$H$21:$I$29,2,FALSE)*(1+'Inputs & Summary'!$C$11)^(33-1),0) -> 77252.483 | O37: =H37+N37 -> 351322.11 | P37: =O37/(1+'Inputs & Summary'!$C$11)^(33-1) -> 136431.39
A38: 34 | B38: ='Inputs & Summary'!$C$7+34-1 -> 83 | C38: =IFERROR(VLOOKUP(B38,'Life Expectancy'!$A$6:$B$81,2,FALSE),1.5) -> 8.8 | D38: ='4% Rule'!C38 -> 0.06 | E38: =MAX(L37,0) -> 4551382.9 | F38: =E38/MAX(C38,1) -> 517202.6 | G38: =MIN('Inputs & Summary'!$C$14*E38,MAX('Inputs & Summary'!$C$13*E38,F38)) -> 273082.97 | H38: =MIN(MIN(H37*(1+'Inputs & Summary'!$C$15),MAX(H37*(1-'Inputs & Summary'!$C$15),G38)),E38) -> 273082.97 | I38: =H38/(1+'Inputs & Summary'!$C$11)^(34-1) -> 102959.45 | J38: =IFERROR(H38/E38,0) -> 0.06 | K38: =(E38-H38)*D38 -> 256698 | L38: =E38-H38+K38 -> 4534997.9 | M38: =L38/(1+'Inputs & Summary'!$C$11)^(34-1) -> 1709813.2 | N38: =IF(B38>='Inputs & Summary'!$C$18,'Inputs & Summary'!$C$17*VLOOKUP('Inputs & Summary'!$C$18,'Inputs & Summary'!$H$21:$I$29,2,FALSE)*(1+'Inputs & Summary'!$C$11)^(34-1),0) -> 79570.057 | O38: =H38+N38 -> 352653.03 | P38: =O38/(1+'Inputs & Summary'!$C$11)^(34-1) -> 132959.45
A39: 35 | B39: ='Inputs & Summary'!$C$7+35-1 -> 84 | C39: =IFERROR(VLOOKUP(B39,'Life Expectancy'!$A$6:$B$81,2,FALSE),1.5) -> 8.3 | D39: ='4% Rule'!C39 -> 0.06 | E39: =MAX(L38,0) -> 4534997.9 | F39: =E39/MAX(C39,1) -> 546385.29 | G39: =MIN('Inputs & Summary'!$C$14*E39,MAX('Inputs & Summary'!$C$13*E39,F39)) -> 272099.88 | H39: =MIN(MIN(H38*(1+'Inputs & Summary'!$C$15),MAX(H38*(1-'Inputs & Summary'!$C$15),G39)),E39) -> 272099.88 | I39: =H39/(1+'Inputs & Summary'!$C$11)^(35-1) -> 99600.772 | J39: =IFERROR(H39/E39,0) -> 0.06 | K39: =(E39-H39)*D39 -> 255773.88 | L39: =E39-H39+K39 -> 4518671.9 | M39: =L39/(1+'Inputs & Summary'!$C$11)^(35-1) -> 1654036.8 | N39: =IF(B39>='Inputs & Summary'!$C$18,'Inputs & Summary'!$C$17*VLOOKUP('Inputs & Summary'!$C$18,'Inputs & Summary'!$H$21:$I$29,2,FALSE)*(1+'Inputs & Summary'!$C$11)^(35-1),0) -> 81957.159 | O39: =H39+N39 -> 354057.03 | P39: =O39/(1+'Inputs & Summary'!$C$11)^(35-1) -> 129600.77
A40: 36 | B40: ='Inputs & Summary'!$C$7+36-1 -> 85 | C40: =IFERROR(VLOOKUP(B40,'Life Expectancy'!$A$6:$B$81,2,FALSE),1.5) -> 7.8 | D40: ='4% Rule'!C40 -> 0.06 | E40: =MAX(L39,0) -> 4518671.9 | F40: =E40/MAX(C40,1) -> 579316.91 | G40: =MIN('Inputs & Summary'!$C$14*E40,MAX('Inputs & Summary'!$C$13*E40,F40)) -> 271120.32 | H40: =MIN(MIN(H39*(1+'Inputs & Summary'!$C$15),MAX(H39*(1-'Inputs & Summary'!$C$15),G40)),E40) -> 271120.32 | I40: =H40/(1+'Inputs & Summary'!$C$11)^(36-1) -> 96351.659 | J40: =IFERROR(H40/E40,0) -> 0.06 | K40: =(E40-H40)*D40 -> 254853.1 | L40: =E40-H40+K40 -> 4502404.7 | M40: =L40/(1+'Inputs & Summary'!$C$11)^(36-1) -> 1600079.9 | N40: =IF(B40>='Inputs & Summary'!$C$18,'Inputs & Summary'!$C$17*VLOOKUP('Inputs & Summary'!$C$18,'Inputs & Summary'!$H$21:$I$29,2,FALSE)*(1+'Inputs & Summary'!$C$11)^(36-1),0) -> 84415.874 | O40: =H40+N40 -> 355536.19 | P40: =O40/(1+'Inputs & Summary'!$C$11)^(36-1) -> 126351.66
A41: 37 | B41: ='Inputs & Summary'!$C$7+37-1 -> 86 | C41: =IFERROR(VLOOKUP(B41,'Life Expectancy'!$A$6:$B$81,2,FALSE),1.5) -> 7.4 | D41: ='4% Rule'!C41 -> 0.06 | E41: =MAX(L40,0) -> 4502404.7 | F41: =E41/MAX(C41,1) -> 608433.07 | G41: =MIN('Inputs & Summary'!$C$14*E41,MAX('Inputs & Summary'!$C$13*E41,F41)) -> 270144.28 | H41: =MIN(MIN(H40*(1+'Inputs & Summary'!$C$15),MAX(H40*(1-'Inputs & Summary'!$C$15),G41)),E41) -> 270144.28 | I41: =H41/(1+'Inputs & Summary'!$C$11)^(37-1) -> 93208.537 | J41: =IFERROR(H41/E41,0) -> 0.06 | K41: =(E41-H41)*D41 -> 253935.63 | L41: =E41-H41+K41 -> 4486196.1 | M41: =L41/(1+'Inputs & Summary'!$C$11)^(37-1) -> 1547883.1 | N41: =IF(B41>='Inputs & Summary'!$C$18,'Inputs & Summary'!$C$17*VLOOKUP('Inputs & Summary'!$C$18,'Inputs & Summary'!$H$21:$I$29,2,FALSE)*(1+'Inputs & Summary'!$C$11)^(37-1),0) -> 86948.35 | O41: =H41+N41 -> 357092.63 | P41: =O41/(1+'Inputs & Summary'!$C$11)^(37-1) -> 123208.54
...

Sheet 4% Rule
A1: 4% Rule — Year by Year
A2: Year-1 withdrawal = 4% of the starting portfolio, then grown by inflation. The Annual return column is calculated from the Market scenario you choose on the Inputs & Summary tab.
A4: Year | B4: Age | C4: Annual return | D4: Beginning balance | E4: Withdrawal | F4: Withdrawal (today's $) | G4: Investment return | H4: Ending balance | I4: Ending balance (today's $)
A5: 1 | B5: ='Inputs & Summary'!$C$7+1-1 -> 50 | C5: =IF('Inputs & Summary'!$C$22="Steady",'Inputs & Summary'!$C$10,IF('Inputs & Summary'!$C$22="Early crash",IFERROR(VLOOKUP(A5,'Inputs & Summary'!$H$7:$J$16,2,FALSE),'Inputs & Summary'!$C$10),IFERROR(VLOOKUP(A5,'Inputs & Summary'!$H$7:$J$16,3,FALSE),'Inputs & Summary'!$C$10))) -> 0.06 | D5: ='Inputs & Summary'!$C$9 -> 3500000 | E5: =MIN(IF('Inputs & Summary'!$C$19>0,'Inputs & Summary'!$C$19,'Inputs & Summary'!$C$9*'Inputs & Summary'!$C$12),D5) -> 140000 | F5: =E5/(1+'Inputs & Summary'!$C$11)^(1-1) -> 140000 | G5: =(D5-E5)*C5 -> 201600 | H5: =D5-E5+G5 -> 3561600 | I5: =H5/(1+'Inputs & Summary'!$C$11)^(1-1) -> 3561600
A6: 2 | B6: ='Inputs & Summary'!$C$7+2-1 -> 51 | C6: =IF('Inputs & Summary'!$C$22="Steady",'Inputs & Summary'!$C$10,IF('Inputs & Summary'!$C$22="Early crash",IFERROR(VLOOKUP(A6,'Inputs & Summary'!$H$7:$J$16,2,FALSE),'Inputs & Summary'!$C$10),IFERROR(VLOOKUP(A6,'Inputs & Summary'!$H$7:$J$16,3,FALSE),'Inputs & Summary'!$C$10))) -> 0.06 | D6: =MAX(H5,0) -> 3561600 | E6: =MIN(E5*(1+'Inputs & Summary'!$C$11),D6) -> 144200 | F6: =E6/(1+'Inputs & Summary'!$C$11)^(2-1) -> 140000 | G6: =(D6-E6)*C6 -> 205044 | H6: =D6-E6+G6 -> 3622444 | I6: =H6/(1+'Inputs & Summary'!$C$11)^(2-1) -> 3516935.9
A7: 3 | B7: ='Inputs & Summary'!$C$7+3-1 -> 52 | C7: =IF('Inputs & Summary'!$C$22="Steady",'Inputs & Summary'!$C$10,IF('Inputs & Summary'!$C$22="Early crash",IFERROR(VLOOKUP(A7,'Inputs & Summary'!$H$7:$J$16,2,FALSE),'Inputs & Summary'!$C$10),IFERROR(VLOOKUP(A7,'Inputs & Summary'!$H$7:$J$16,3,FALSE),'Inputs & Summary'!$C$10))) -> 0.06 | D7: =MAX(H6,0) -> 3622444 | E7: =MIN(E6*(1+'Inputs & Summary'!$C$11),D7) -> 148526 | F7: =E7/(1+'Inputs & Summary'!$C$11)^(3-1) -> 140000 | G7: =(D7-E7)*C7 -> 208435.08 | H7: =D7-E7+G7 -> 3682353.1 | I7: =H7/(1+'Inputs & Summary'!$C$11)^(3-1) -> 3470970.9
A8: 4 | B8: ='Inputs & Summary'!$C$7+4-1 -> 53 | C8: =IF('Inputs & Summary'!$C$22="Steady",'Inputs & Summary'!$C$10,IF('Inputs & Summary'!$C$22="Early crash",IFERROR(VLOOKUP(A8,'Inputs & Summary'!$H$7:$J$16,2,FALSE),'Inputs & Summary'!$C$10),IFERROR(VLOOKUP(A8,'Inputs & Summary'!$H$7:$J$16,3,FALSE),'Inputs & Summary'!$C$10))) -> 0.06 | D8: =MAX(H7,0) -> 3682353.1 | E8: =MIN(E7*(1+'Inputs & Summary'!$C$11),D8) -> 152981.78 | F8: =E8/(1+'Inputs & Summary'!$C$11)^(4-1) -> 140000 | G8: =(D8-E8)*C8 -> 211762.28 | H8: =D8-E8+G8 -> 3741133.6 | I8: =H8/(1+'Inputs & Summary'!$C$11)^(4-1) -> 3423667.2
A9: 5 | B9: ='Inputs & Summary'!$C$7+5-1 -> 54 | C9: =IF('Inputs & Summary'!$C$22="Steady",'Inputs & Summary'!$C$10,IF('Inputs & Summary'!$C$22="Early crash",IFERROR(VLOOKUP(A9,'Inputs & Summary'!$H$7:$J$16,2,FALSE),'Inputs & Summary'!$C$10),IFERROR(VLOOKUP(A9,'Inputs & Summary'!$H$7:$J$16,3,FALSE),'Inputs & Summary'!$C$10))) -> 0.06 | D9: =MAX(H8,0) -> 3741133.6 | E9: =MIN(E8*(1+'Inputs & Summary'!$C$11),D9) -> 157571.23 | F9: =E9/(1+'Inputs & Summary'!$C$11)^(5-1) -> 140000 | G9: =(D9-E9)*C9 -> 215013.74 | H9: =D9-E9+G9 -> 3798576.1 | I9: =H9/(1+'Inputs & Summary'!$C$11)^(5-1) -> 3374985.7
A10: 6 | B10: ='Inputs & Summary'!$C$7+6-1 -> 55 | C10: =IF('Inputs & Summary'!$C$22="Steady",'Inputs & Summary'!$C$10,IF('Inputs & Summary'!$C$22="Early crash",IFERROR(VLOOKUP(A10,'Inputs & Summary'!$H$7:$J$16,2,FALSE),'Inputs & Summary'!$C$10),IFERROR(VLOOKUP(A10,'Inputs & Summary'!$H$7:$J$16,3,FALSE),'Inputs & Summary'!$C$10))) -> 0.06 | D10: =MAX(H9,0) -> 3798576.1 | E10: =MIN(E9*(1+'Inputs & Summary'!$C$11),D10) -> 162298.37 | F10: =E10/(1+'Inputs & Summary'!$C$11)^(6-1) -> 140000 | G10: =(D10-E10)*C10 -> 218176.66 | H10: =D10-E10+G10 -> 3854454.4 | I10: =H10/(1+'Inputs & Summary'!$C$11)^(6-1) -> 3324886.2
A11: 7 | B11: ='Inputs & Summary'!$C$7+7-1 -> 56 | C11: =IF('Inputs & Summary'!$C$22="Steady",'Inputs & Summary'!$C$10,IF('Inputs & Summary'!$C$22="Early crash",IFERROR(VLOOKUP(A11,'Inputs & Summary'!$H$7:$J$16,2,FALSE),'Inputs & Summary'!$C$10),IFERROR(VLOOKUP(A11,'Inputs & Summary'!$H$7:$J$16,3,FALSE),'Inputs & Summary'!$C$10))) -> 0.06 | D11: =MAX(H10,0) -> 3854454.4 | E11: =MIN(E10*(1+'Inputs & Summary'!$C$11),D11) -> 167167.32 | F11: =E11/(1+'Inputs & Summary'!$C$11)^(7-1) -> 140000 | G11: =(D11-E11)*C11 -> 221237.22 | H11: =D11-E11+G11 -> 3908524.3 | I11: =H11/(1+'Inputs & Summary'!$C$11)^(7-1) -> 3273327.6
A12: 8 | B12: ='Inputs & Summary'!$C$7+8-1 -> 57 | C12: =IF('Inputs & Summary'!$C$22="Steady",'Inputs & Summary'!$C$10,IF('Inputs & Summary'!$C$22="Early crash",IFERROR(VLOOKUP(A12,'Inputs & Summary'!$H$7:$J$16,2,FALSE),'Inputs & Summary'!$C$10),IFERROR(VLOOKUP(A12,'Inputs & Summary'!$H$7:$J$16,3,FALSE),'Inputs & Summary'!$C$10))) -> 0.06 | D12: =MAX(H11,0) -> 3908524.3 | E12: =MIN(E11*(1+'Inputs & Summary'!$C$11),D12) -> 172182.34 | F12: =E12/(1+'Inputs & Summary'!$C$11)^(8-1) -> 140000 | G12: =(D12-E12)*C12 -> 224180.52 | H12: =D12-E12+G12 -> 3960522.5 | I12: =H12/(1+'Inputs & Summary'!$C$11)^(8-1) -> 3220267.2
A13: 9 | B13: ='Inputs & Summary'!$C$7+9-1 -> 58 | C13: =IF('Inputs & Summary'!$C$22="Steady",'Inputs & Summary'!$C$10,IF('Inputs & Summary'!$C$22="Early crash",IFERROR(VLOOKUP(A13,'Inputs & Summary'!$H$7:$J$16,2,FALSE),'Inputs & Summary'!$C$10),IFERROR(VLOOKUP(A13,'Inputs & Summary'!$H$7:$J$16,3,FALSE),'Inputs & Summary'!$C$10))) -> 0.06 | D13: =MAX(H12,0) -> 3960522.5 | E13: =MIN(E12*(1+'Inputs & Summary'!$C$11),D13) -> 177347.81 | F13: =E13/(1+'Inputs & Summary'!$C$11)^(9-1) -> 140000 | G13: =(D13-E13)*C13 -> 226990.48 | H13: =D13-E13+G13 -> 4010165.1 | I13: =H13/(1+'Inputs & Summary'!$C$11)^(9-1) -> 3165661.4
A14: 10 | B14: ='Inputs & Summary'!$C$7+10-1 -> 59 | C14: =IF('Inputs & Summary'!$C$22="Steady",'Inputs & Summary'!$C$10,IF('Inputs & Summary'!$C$22="Early crash",IFERROR(VLOOKUP(A14,'Inputs & Summary'!$H$7:$J$16,2,FALSE),'Inputs & Summary'!$C$10),IFERROR(VLOOKUP(A14,'Inputs & Summary'!$H$7:$J$16,3,FALSE),'Inputs & Summary'!$C$10))) -> 0.06 | D14: =MAX(H13,0) -> 4010165.1 | E14: =MIN(E13*(1+'Inputs & Summary'!$C$11),D14) -> 182668.25 | F14: =E14/(1+'Inputs & Summary'!$C$11)^(10-1) -> 140000 | G14: =(D14-E14)*C14 -> 229649.81 | H14: =D14-E14+G14 -> 4057146.7 | I14: =H14/(1+'Inputs & Summary'!$C$11)^(10-1) -> 3109465.1
A15: 11 | B15: ='Inputs & Summary'!$C$7+11-1 -> 60 | C15: =IF('Inputs & Summary'!$C$22="Steady",'Inputs & Summary'!$C$10,IF('Inputs & Summary'!$C$22="Early crash",IFERROR(VLOOKUP(A15,'Inputs & Summary'!$H$7:$J$16,2,FALSE),'Inputs & Summary'!$C$10),IFERROR(VLOOKUP(A15,'Inputs & Summary'!$H$7:$J$16,3,FALSE),'Inputs & Summary'!$C$10))) -> 0.06 | D15: =MAX(H14,0) -> 4057146.7 | E15: =MIN(E14*(1+'Inputs & Summary'!$C$11),D15) -> 188148.29 | F15: =E15/(1+'Inputs & Summary'!$C$11)^(11-1) -> 140000 | G15: =(D15-E15)*C15 -> 232139.9 | H15: =D15-E15+G15 -> 4101138.3 | I15: =H15/(1+'Inputs & Summary'!$C$11)^(11-1) -> 3051632.1
A16: 12 | B16: ='Inputs & Summary'!$C$7+12-1 -> 61 | C16: =IF('Inputs & Summary'!$C$22="Steady",'Inputs & Summary'!$C$10,IF('Inputs & Summary'!$C$22="Early crash",IFERROR(VLOOKUP(A16,'Inputs & Summary'!$H$7:$J$16,2,FALSE),'Inputs & Summary'!$C$10),IFERROR(VLOOKUP(A16,'Inputs & Summary'!$H$7:$J$16,3,FALSE),'Inputs & Summary'!$C$10))) -> 0.06 | D16: =MAX(H15,0) -> 4101138.3 | E16: =MIN(E15*(1+'Inputs & Summary'!$C$11),D16) -> 193792.74 | F16: =E16/(1+'Inputs & Summary'!$C$11)^(12-1) -> 140000 | G16: =(D16-E16)*C16 -> 234440.73 | H16: =D16-E16+G16 -> 4141786.3 | I16: =H16/(1+'Inputs & Summary'!$C$11)^(12-1) -> 2992114.5
A17: 13 | B17: ='Inputs & Summary'!$C$7+13-1 -> 62 | C17: =IF('Inputs & Summary'!$C$22="Steady",'Inputs & Summary'!$C$10,IF('Inputs & Summary'!$C$22="Early crash",IFERROR(VLOOKUP(A17,'Inputs & Summary'!$H$7:$J$16,2,FALSE),'Inputs & Summary'!$C$10),IFERROR(VLOOKUP(A17,'Inputs & Summary'!$H$7:$J$16,3,FALSE),'Inputs & Summary'!$C$10))) -> 0.06 | D17: =MAX(H16,0) -> 4141786.3 | E17: =MIN(E16*(1+'Inputs & Summary'!$C$11),D17) -> 199606.52 | F17: =E17/(1+'Inputs & Summary'!$C$11)^(13-1) -> 140000 | G17: =(D17-E17)*C17 -> 236530.79 | H17: =D17-E17+G17 -> 4178710.6 | I17: =H17/(1+'Inputs & Summary'!$C$11)^(13-1) -> 2930863.5
A18: 14 | B18: ='Inputs & Summary'!$C$7+14-1 -> 63 | C18: =IF('Inputs & Summary'!$C$22="Steady",'Inputs & Summary'!$C$10,IF('Inputs & Summary'!$C$22="Early crash",IFERROR(VLOOKUP(A18,'Inputs & Summary'!$H$7:$J$16,2,FALSE),'Inputs & Summary'!$C$10),IFERROR(VLOOKUP(A18,'Inputs & Summary'!$H$7:$J$16,3,FALSE),'Inputs & Summary'!$C$10))) -> 0.06 | D18: =MAX(H17,0) -> 4178710.6 | E18: =MIN(E17*(1+'Inputs & Summary'!$C$11),D18) -> 205594.72 | F18: =E18/(1+'Inputs & Summary'!$C$11)^(14-1) -> 140000 | G18: =(D18-E18)*C18 -> 238386.95 | H18: =D18-E18+G18 -> 4211502.8 | I18: =H18/(1+'Inputs & Summary'!$C$11)^(14-1) -> 2867828.5
A19: 15 | B19: ='Inputs & Summary'!$C$7+15-1 -> 64 | C19: =IF('Inputs & Summary'!$C$22="Steady",'Inputs & Summary'!$C$10,IF('Inputs & Summary'!$C$22="Early crash",IFERROR(VLOOKUP(A19,'Inputs & Summary'!$H$7:$J$16,2,FALSE),'Inputs & Summary'!$C$10),IFERROR(VLOOKUP(A19,'Inputs & Summary'!$H$7:$J$16,3,FALSE),'Inputs & Summary'!$C$10))) -> 0.06 | D19: =MAX(H18,0) -> 4211502.8 | E19: =MIN(E18*(1+'Inputs & Summary'!$C$11),D19) -> 211762.56 | F19: =E19/(1+'Inputs & Summary'!$C$11)^(15-1) -> 140000 | G19: =(D19-E19)*C19 -> 239984.41 | H19: =D19-E19+G19 -> 4239724.6 | I19: =H19/(1+'Inputs & Summary'!$C$11)^(15-1) -> 2802957.4
A20: 16 | B20: ='Inputs & Summary'!$C$7+16-1 -> 65 | C20: =IF('Inputs & Summary'!$C$22="Steady",'Inputs & Summary'!$C$10,IF('Inputs & Summary'!$C$22="Early crash",IFERROR(VLOOKUP(A20,'Inputs & Summary'!$H$7:$J$16,2,FALSE),'Inputs & Summary'!$C$10),IFERROR(VLOOKUP(A20,'Inputs & Summary'!$H$7:$J$16,3,FALSE),'Inputs & Summary'!$C$10))) -> 0.06 | D20: =MAX(H19,0) -> 4239724.6 | E20: =MIN(E19*(1+'Inputs & Summary'!$C$11),D20) -> 218115.44 | F20: =E20/(1+'Inputs & Summary'!$C$11)^(16-1) -> 140000 | G20: =(D20-E20)*C20 -> 241296.55 | H20: =D20-E20+G20 -> 4262905.7 | I20: =H20/(1+'Inputs & Summary'!$C$11)^(16-1) -> 2736197
A21: 17 | B21: ='Inputs & Summary'!$C$7+17-1 -> 66 | C21: =IF('Inputs & Summary'!$C$22="Steady",'Inputs & Summary'!$C$10,IF('Inputs & Summary'!$C$22="Early crash",IFERROR(VLOOKUP(A21,'Inputs & Summary'!$H$7:$J$16,2,FALSE),'Inputs & Summary'!$C$10),IFERROR(VLOOKUP(A21,'Inputs & Summary'!$H$7:$J$16,3,FALSE),'Inputs & Summary'!$C$10))) -> 0.06 | D21: =MAX(H20,0) -> 4262905.7 | E21: =MIN(E20*(1+'Inputs & Summary'!$C$11),D21) -> 224658.9 | F21: =E21/(1+'Inputs & Summary'!$C$11)^(17-1) -> 140000 | G21: =(D21-E21)*C21 -> 242294.81 | H21: =D21-E21+G21 -> 4280541.7 | I21: =H21/(1+'Inputs & Summary'!$C$11)^(17-1) -> 2667492
A22: 18 | B22: ='Inputs & Summary'!$C$7+18-1 -> 67 | C22: =IF('Inputs & Summary'!$C$22="Steady",'Inputs & Summary'!$C$10,IF('Inputs & Summary'!$C$22="Early crash",IFERROR(VLOOKUP(A22,'Inputs & Summary'!$H$7:$J$16,2,FALSE),'Inputs & Summary'!$C$10),IFERROR(VLOOKUP(A22,'Inputs & Summary'!$H$7:$J$16,3,FALSE),'Inputs & Summary'!$C$10))) -> 0.06 | D22: =MAX(H21,0) -> 4280541.7 | E22: =MIN(E21*(1+'Inputs & Summary'!$C$11),D22) -> 231398.67 | F22: =E22/(1+'Inputs & Summary'!$C$11)^(18-1) -> 140000 | G22: =(D22-E22)*C22 -> 242948.58 | H22: =D22-E22+G22 -> 4292091.6 | I22: =H22/(1+'Inputs & Summary'!$C$11)^(18-1) -> 2596786
A23: 19 | B23: ='Inputs & Summary'!$C$7+19-1 -> 68 | C23: =IF('Inputs & Summary'!$C$22="Steady",'Inputs & Summary'!$C$10,IF('Inputs & Summary'!$C$22="Early crash",IFERROR(VLOOKUP(A23,'Inputs & Summary'!$H$7:$J$16,2,FALSE),'Inputs & Summary'!$C$10),IFERROR(VLOOKUP(A23,'Inputs & Summary'!$H$7:$J$16,3,FALSE),'Inputs & Summary'!$C$10))) -> 0.06 | D23: =MAX(H22,0) -> 4292091.6 | E23: =MIN(E22*(1+'Inputs & Summary'!$C$11),D23) -> 238340.63 | F23: =E23/(1+'Inputs & Summary'!$C$11)^(19-1) -> 140000 | G23: =(D23-E23)*C23 -> 243225.06 | H23: =D23-E23+G23 -> 4296976 | I23: =H23/(1+'Inputs & Summary'!$C$11)^(19-1) -> 2524020.5
A24: 20 | B24: ='Inputs & Summary'!$C$7+20-1 -> 69 | C24: =IF('Inputs & Summary'!$C$22="Steady",'Inputs & Summary'!$C$10,IF('Inputs & Summary'!$C$22="Early crash",IFERROR(VLOOKUP(A24,'Inputs & Summary'!$H$7:$J$16,2,FALSE),'Inputs & Summary'!$C$10),IFERROR(VLOOKUP(A24,'Inputs & Summary'!$H$7:$J$16,3,FALSE),'Inputs & Summary'!$C$10))) -> 0.06 | D24: =MAX(H23,0) -> 4296976 | E24: =MIN(E23*(1+'Inputs & Summary'!$C$11),D24) -> 245490.85 | F24: =E24/(1+'Inputs & Summary'!$C$11)^(20-1) -> 140000 | G24: =(D24-E24)*C24 -> 243089.11 | H24: =D24-E24+G24 -> 4294574.3 | I24: =H24/(1+'Inputs & Summary'!$C$11)^(20-1) -> 2449135.7
A25: 21 | B25: ='Inputs & Summary'!$C$7+21-1 -> 70 | C25: =IF('Inputs & Summary'!$C$22="Steady",'Inputs & Summary'!$C$10,IF('Inputs & Summary'!$C$22="Early crash",IFERROR(VLOOKUP(A25,'Inputs & Summary'!$H$7:$J$16,2,FALSE),'Inputs & Summary'!$C$10),IFERROR(VLOOKUP(A25,'Inputs & Summary'!$H$7:$J$16,3,FALSE),'Inputs & Summary'!$C$10))) -> 0.06 | D25: =MAX(H24,0) -> 4294574.3 | E25: =MIN(E24*(1+'Inputs & Summary'!$C$11),D25) -> 252855.57 | F25: =E25/(1+'Inputs & Summary'!$C$11)^(21-1) -> 140000 | G25: =(D25-E25)*C25 -> 242503.12 | H25: =D25-E25+G25 -> 4284221.8 | I25: =H25/(1+'Inputs & Summary'!$C$11)^(21-1) -> 2372069.7
A26: 22 | B26: ='Inputs & Summary'!$C$7+22-1 -> 71 | C26: =IF('Inputs & Summary'!$C$22="Steady",'Inputs & Summary'!$C$10,IF('Inputs & Summary'!$C$22="Early crash",IFERROR(VLOOKUP(A26,'Inputs & Summary'!$H$7:$J$16,2,FALSE),'Inputs & Summary'!$C$10),IFERROR(VLOOKUP(A26,'Inputs & Summary'!$H$7:$J$16,3,FALSE),'Inputs & Summary'!$C$10))) -> 0.06 | D26: =MAX(H25,0) -> 4284221.8 | E26: =MIN(E25*(1+'Inputs & Summary'!$C$11),D26) -> 260441.24 | F26: =E26/(1+'Inputs & Summary'!$C$11)^(22-1) -> 140000 | G26: =(D26-E26)*C26 -> 241426.83 | H26: =D26-E26+G26 -> 4265207.4 | I26: =H26/(1+'Inputs & Summary'!$C$11)^(22-1) -> 2292759.1
A27: 23 | B27: ='Inputs & Summary'!$C$7+23-1 -> 72 | C27: =IF('Inputs & Summary'!$C$22="Steady",'Inputs & Summary'!$C$10,IF('Inputs & Summary'!$C$22="Early crash",IFERROR(VLOOKUP(A27,'Inputs & Summary'!$H$7:$J$16,2,FALSE),'Inputs & Summary'!$C$10),IFERROR(VLOOKUP(A27,'Inputs & Summary'!$H$7:$J$16,3,FALSE),'Inputs & Summary'!$C$10))) -> 0.06 | D27: =MAX(H26,0) -> 4265207.4 | E27: =MIN(E26*(1+'Inputs & Summary'!$C$11),D27) -> 268254.48 | F27: =E27/(1+'Inputs & Summary'!$C$11)^(23-1) -> 140000 | G27: =(D27-E27)*C27 -> 239817.18 | H27: =D27-E27+G27 -> 4236770.1 | I27: =H27/(1+'Inputs & Summary'!$C$11)^(23-1) -> 2211138.5
A28: 24 | B28: ='Inputs & Summary'!$C$7+24-1 -> 73 | C28: =IF('Inputs & Summary'!$C$22="Steady",'Inputs & Summary'!$C$10,IF('Inputs & Summary'!$C$22="Early crash",IFERROR(VLOOKUP(A28,'Inputs & Summary'!$H$7:$J$16,2,FALSE),'Inputs & Summary'!$C$10),IFERROR(VLOOKUP(A28,'Inputs & Summary'!$H$7:$J$16,3,FALSE),'Inputs & Summary'!$C$10))) -> 0.06 | D28: =MAX(H27,0) -> 4236770.1 | E28: =MIN(E27*(1+'Inputs & Summary'!$C$11),D28) -> 276302.11 | F28: =E28/(1+'Inputs & Summary'!$C$11)^(24-1) -> 140000 | G28: =(D28-E28)*C28 -> 237628.08 | H28: =D28-E28+G28 -> 4198096.1 | I28: =H28/(1+'Inputs & Summary'!$C$11)^(24-1) -> 2127140.6
A29: 25 | B29: ='Inputs & Summary'!$C$7+25-1 -> 74 | C29: =IF('Inputs & Summary'!$C$22="Steady",'Inputs & Summary'!$C$10,IF('Inputs & Summary'!$C$22="Early crash",IFERROR(VLOOKUP(A29,'Inputs & Summary'!$H$7:$J$16,2,FALSE),'Inputs & Summary'!$C$10),IFERROR(VLOOKUP(A29,'Inputs & Summary'!$H$7:$J$16,3,FALSE),'Inputs & Summary'!$C$10))) -> 0.06 | D29: =MAX(H28,0) -> 4198096.1 | E29: =MIN(E28*(1+'Inputs & Summary'!$C$11),D29) -> 284591.17 | F29: =E29/(1+'Inputs & Summary'!$C$11)^(25-1) -> 140000 | G29: =(D29-E29)*C29 -> 234810.29 | H29: =D29-E29+G29 -> 4148315.2 | I29: =H29/(1+'Inputs & Summary'!$C$11)^(25-1) -> 2040696.2
A30: 26 | B30: ='Inputs & Summary'!$C$7+26-1 -> 75 | C30: =IF('Inputs & Summary'!$C$22="Steady",'Inputs & Summary'!$C$10,IF('Inputs & Summary'!$C$22="Early crash",IFERROR(VLOOKUP(A30,'Inputs & Summary'!$H$7:$J$16,2,FALSE),'Inputs & Summary'!$C$10),IFERROR(VLOOKUP(A30,'Inputs & Summary'!$H$7:$J$16,3,FALSE),'Inputs & Summary'!$C$10))) -> 0.06 | D30: =MAX(H29,0) -> 4148315.2 | E30: =MIN(E29*(1+'Inputs & Summary'!$C$11),D30) -> 293128.91 | F30: =E30/(1+'Inputs & Summary'!$C$11)^(26-1) -> 140000 | G30: =(D30-E30)*C30 -> 231311.18 | H30: =D30-E30+G30 -> 4086497.5 | I30: =H30/(1+'Inputs & Summary'!$C$11)^(26-1) -> 1951733.9
A31: 27 | B31: ='Inputs & Summary'!$C$7+27-1 -> 76 | C31: =IF('Inputs & Summary'!$C$22="Steady",'Inputs & Summary'!$C$10,IF('Inputs & Summary'!$C$22="Early crash",IFERROR(VLOOKUP(A31,'Inputs & Summary'!$H$7:$J$16,2,FALSE),'Inputs & Summary'!$C$10),IFERROR(VLOOKUP(A31,'Inputs & Summary'!$H$7:$J$16,3,FALSE),'Inputs & Summary'!$C$10))) -> 0.06 | D31: =MAX(H30,0) -> 4086497.5 | E31: =MIN(E30*(1+'Inputs & Summary'!$C$11),D31) -> 301922.78 | F31: =E31/(1+'Inputs & Summary'!$C$11)^(27-1) -> 140000 | G31: =(D31-E31)*C31 -> 227074.48 | H31: =D31-E31+G31 -> 4011649.2 | I31: =H31/(1+'Inputs & Summary'!$C$11)^(27-1) -> 1860180.6
A32: 28 | B32: ='Inputs & Summary'!$C$7+28-1 -> 77 | C32: =IF('Inputs & Summary'!$C$22="Steady",'Inputs & Summary'!$C$10,IF('Inputs & Summary'!$C$22="Early crash",IFERROR(VLOOKUP(A32,'Inputs & Summary'!$H$7:$J$16,2,FALSE),'Inputs & Summary'!$C$10),IFERROR(VLOOKUP(A32,'Inputs & Summary'!$H$7:$J$16,3,FALSE),'Inputs & Summary'!$C$10))) -> 0.06 | D32: =MAX(H31,0) -> 4011649.2 | E32: =MIN(E31*(1+'Inputs & Summary'!$C$11),D32) -> 310980.46 | F32: =E32/(1+'Inputs & Summary'!$C$11)^(28-1) -> 140000 | G32: =(D32-E32)*C32 -> 222040.12 | H32: =D32-E32+G32 -> 3922708.8 | I32: =H32/(1+'Inputs & Summary'!$C$11)^(28-1) -> 1765960.6
A33: 29 | B33: ='Inputs & Summary'!$C$7+29-1 -> 78 | C33: =IF('Inputs & Summary'!$C$22="Steady",'Inputs & Summary'!$C$10,IF('Inputs & Summary'!$C$22="Early crash",IFERROR(VLOOKUP(A33,'Inputs & Summary'!$H$7:$J$16,2,FALSE),'Inputs & Summary'!$C$10),IFERROR(VLOOKUP(A33,'Inputs & Summary'!$H$7:$J$16,3,FALSE),'Inputs & Summary'!$C$10))) -> 0.06 | D33: =MAX(H32,0) -> 3922708.8 | E33: =MIN(E32*(1+'Inputs & Summary'!$C$11),D33) -> 320309.87 | F33: =E33/(1+'Inputs & Summary'!$C$11)^(29-1) -> 140000 | G33: =(D33-E33)*C33 -> 216143.94 | H33: =D33-E33+G33 -> 3818542.9 | I33: =H33/(1+'Inputs & Summary'!$C$11)^(29-1) -> 1668996.3
